==5223== Helgrind, a thread error detector
==5223== Copyright (C) 2007-2017, and GNU GPL'd, by OpenWorks LLP et al.
==5223== Using Valgrind-3.20.0 and LibVEX; rerun with -h for copyright info
==5223== Command: python3 -m pytest -n auto test_segel.py
==5223== Parent PID: 9
==5223== 
==5223== ---Thread-Announcement------------------------------------------
==5223== 
==5223== Thread #2 was created
==5223==    at 0x4EC2763: clone (clone.S:76)
==5223==    by 0x4EC2820: __clone_internal (clone-internal.c:83)
==5223==    by 0x4E3C50F: create_thread (pthread_create.c:297)
==5223==    by 0x4E3D073: pthread_create@@GLIBC_2.34 (pthread_create.c:833)
==5223==    by 0x484C7AF: pthread_create_WRK (hg_intercepts.c:445)
==5223==    by 0x484DD35: pthread_create@* (hg_intercepts.c:478)
==5223==    by 0x4AC5317: PyThread_start_new_thread (thread_pthread.h:289)
==5223==    by 0x4AF710D: thread_PyThread_start_new_thread (_threadmodule.c:1162)
==5223==    by 0x4A2C2B7: cfunction_call (methodobject.c:553)
==5223==    by 0x4A0FA92: _PyObject_MakeTpCall (call.c:214)
==5223==    by 0x4A183D8: _PyEval_EvalFrameDefault (ceval.c:4773)
==5223==    by 0x4A144A9: UnknownInlinedFun (pycore_ceval.h:73)
==5223==    by 0x4A144A9: _PyEval_Vector (ceval.c:6438)
==5223== 
==5223== ----------------------------------------------------------------
==5223== 
==5223== Thread #2: pthread_cond_{signal,broadcast}: dubious: associated lock is not held by any thread
==5223==    at 0x4849F1F: pthread_cond_signal_WRK (hg_intercepts.c:1565)
==5223==    by 0x484E1F5: pthread_cond_signal@* (hg_intercepts.c:1586)
==5223==    by 0x4E3BFB5: __pthread_cond_wait_common (pthread_cond_wait.c:516)
==5223==    by 0x4E3BFB5: pthread_cond_timedwait@@GLIBC_2.3.2 (pthread_cond_wait.c:643)
==5223==    by 0x484CE9E: pthread_cond_timedwait_WRK (hg_intercepts.c:1387)
==5223==    by 0x484E1D1: pthread_cond_timedwait@* (hg_intercepts.c:1422)
==5223==    by 0x49FDE72: UnknownInlinedFun (condvar.h:73)
==5223==    by 0x49FDE72: take_gil (ceval_gil.h:250)
==5223==    by 0x4AF7375: PyEval_AcquireThread (ceval.c:456)
==5223==    by 0x4AF72E5: thread_run (_threadmodule.c:1089)
==5223==    by 0x4AC5447: pythread_wrapper (thread_pthread.h:241)
==5223==    by 0x484C9A9: mythread_wrapper (hg_intercepts.c:406)
==5223==    by 0x4E3C906: start_thread (pthread_create.c:444)
==5223==    by 0x4EC2773: clone (clone.S:100)
==5223== 
==5223== ---Thread-Announcement------------------------------------------
==5223== 
==5223== Thread #3 was created
==5223==    at 0x4EC2763: clone (clone.S:76)
==5223==    by 0x4EC2820: __clone_internal (clone-internal.c:83)
==5223==    by 0x4E3C50F: create_thread (pthread_create.c:297)
==5223==    by 0x4E3D073: pthread_create@@GLIBC_2.34 (pthread_create.c:833)
==5223==    by 0x484C7AF: pthread_create_WRK (hg_intercepts.c:445)
==5223==    by 0x484DD35: pthread_create@* (hg_intercepts.c:478)
==5223==    by 0x4AC5317: PyThread_start_new_thread (thread_pthread.h:289)
==5223==    by 0x4AF710D: thread_PyThread_start_new_thread (_threadmodule.c:1162)
==5223==    by 0x4A2C2B7: cfunction_call (methodobject.c:553)
==5223==    by 0x4A0FA92: _PyObject_MakeTpCall (call.c:214)
==5223==    by 0x4A183D8: _PyEval_EvalFrameDefault (ceval.c:4773)
==5223==    by 0x4A144A9: UnknownInlinedFun (pycore_ceval.h:73)
==5223==    by 0x4A144A9: _PyEval_Vector (ceval.c:6438)
==5223== 
==5223== ----------------------------------------------------------------
==5223== 
==5223== Thread #3: pthread_cond_{signal,broadcast}: dubious: associated lock is not held by any thread
==5223==    at 0x4849F1F: pthread_cond_signal_WRK (hg_intercepts.c:1565)
==5223==    by 0x484E1F5: pthread_cond_signal@* (hg_intercepts.c:1586)
==5223==    by 0x4E3BFB5: __pthread_cond_wait_common (pthread_cond_wait.c:516)
==5223==    by 0x4E3BFB5: pthread_cond_timedwait@@GLIBC_2.3.2 (pthread_cond_wait.c:643)
==5223==    by 0x484CE9E: pthread_cond_timedwait_WRK (hg_intercepts.c:1387)
==5223==    by 0x484E1D1: pthread_cond_timedwait@* (hg_intercepts.c:1422)
==5223==    by 0x49FDE72: UnknownInlinedFun (condvar.h:73)
==5223==    by 0x49FDE72: take_gil (ceval_gil.h:250)
==5223==    by 0x4AF7375: PyEval_AcquireThread (ceval.c:456)
==5223==    by 0x4AF72E5: thread_run (_threadmodule.c:1089)
==5223==    by 0x4AC5447: pythread_wrapper (thread_pthread.h:241)
==5223==    by 0x484C9A9: mythread_wrapper (hg_intercepts.c:406)
==5223==    by 0x4E3C906: start_thread (pthread_create.c:444)
==5223==    by 0x4EC2773: clone (clone.S:100)
==5223== 
==5223== ---Thread-Announcement------------------------------------------
==5223== 
==5223== Thread #4 was created
==5223==    at 0x4EC2763: clone (clone.S:76)
==5223==    by 0x4EC2820: __clone_internal (clone-internal.c:83)
==5223==    by 0x4E3C50F: create_thread (pthread_create.c:297)
==5223==    by 0x4E3D073: pthread_create@@GLIBC_2.34 (pthread_create.c:833)
==5223==    by 0x484C7AF: pthread_create_WRK (hg_intercepts.c:445)
==5223==    by 0x484DD35: pthread_create@* (hg_intercepts.c:478)
==5223==    by 0x4AC5317: PyThread_start_new_thread (thread_pthread.h:289)
==5223==    by 0x4AF710D: thread_PyThread_start_new_thread (_threadmodule.c:1162)
==5223==    by 0x4A2C2B7: cfunction_call (methodobject.c:553)
==5223==    by 0x4A0FA92: _PyObject_MakeTpCall (call.c:214)
==5223==    by 0x4A183D8: _PyEval_EvalFrameDefault (ceval.c:4773)
==5223==    by 0x4A144A9: UnknownInlinedFun (pycore_ceval.h:73)
==5223==    by 0x4A144A9: _PyEval_Vector (ceval.c:6438)
==5223== 
==5223== ----------------------------------------------------------------
==5223== 
==5223== Thread #4: pthread_cond_{signal,broadcast}: dubious: associated lock is not held by any thread
==5223==    at 0x4849F1F: pthread_cond_signal_WRK (hg_intercepts.c:1565)
==5223==    by 0x484E1F5: pthread_cond_signal@* (hg_intercepts.c:1586)
==5223==    by 0x4E3BFB5: __pthread_cond_wait_common (pthread_cond_wait.c:516)
==5223==    by 0x4E3BFB5: pthread_cond_timedwait@@GLIBC_2.3.2 (pthread_cond_wait.c:643)
==5223==    by 0x484CE9E: pthread_cond_timedwait_WRK (hg_intercepts.c:1387)
==5223==    by 0x484E1D1: pthread_cond_timedwait@* (hg_intercepts.c:1422)
==5223==    by 0x49FDE72: UnknownInlinedFun (condvar.h:73)
==5223==    by 0x49FDE72: take_gil (ceval_gil.h:250)
==5223==    by 0x4AF7375: PyEval_AcquireThread (ceval.c:456)
==5223==    by 0x4AF72E5: thread_run (_threadmodule.c:1089)
==5223==    by 0x4AC5447: pythread_wrapper (thread_pthread.h:241)
==5223==    by 0x484C9A9: mythread_wrapper (hg_intercepts.c:406)
==5223==    by 0x4E3C906: start_thread (pthread_create.c:444)
==5223==    by 0x4EC2773: clone (clone.S:100)
==5223== 
==5223== ---Thread-Announcement------------------------------------------
==5223== 
==5223== Thread #5 was created
==5223==    at 0x4EC2763: clone (clone.S:76)
==5223==    by 0x4EC2820: __clone_internal (clone-internal.c:83)
==5223==    by 0x4E3C50F: create_thread (pthread_create.c:297)
==5223==    by 0x4E3D073: pthread_create@@GLIBC_2.34 (pthread_create.c:833)
==5223==    by 0x484C7AF: pthread_create_WRK (hg_intercepts.c:445)
==5223==    by 0x484DD35: pthread_create@* (hg_intercepts.c:478)
==5223==    by 0x4AC5317: PyThread_start_new_thread (thread_pthread.h:289)
==5223==    by 0x4AF710D: thread_PyThread_start_new_thread (_threadmodule.c:1162)
==5223==    by 0x4A2C2B7: cfunction_call (methodobject.c:553)
==5223==    by 0x4A0FA92: _PyObject_MakeTpCall (call.c:214)
==5223==    by 0x4A183D8: _PyEval_EvalFrameDefault (ceval.c:4773)
==5223==    by 0x4A144A9: UnknownInlinedFun (pycore_ceval.h:73)
==5223==    by 0x4A144A9: _PyEval_Vector (ceval.c:6438)
==5223== 
==5223== ----------------------------------------------------------------
==5223== 
==5223== Thread #5: pthread_cond_{signal,broadcast}: dubious: associated lock is not held by any thread
==5223==    at 0x4849F1F: pthread_cond_signal_WRK (hg_intercepts.c:1565)
==5223==    by 0x484E1F5: pthread_cond_signal@* (hg_intercepts.c:1586)
==5223==    by 0x4E3BFB5: __pthread_cond_wait_common (pthread_cond_wait.c:516)
==5223==    by 0x4E3BFB5: pthread_cond_timedwait@@GLIBC_2.3.2 (pthread_cond_wait.c:643)
==5223==    by 0x484CE9E: pthread_cond_timedwait_WRK (hg_intercepts.c:1387)
==5223==    by 0x484E1D1: pthread_cond_timedwait@* (hg_intercepts.c:1422)
==5223==    by 0x49FDE72: UnknownInlinedFun (condvar.h:73)
==5223==    by 0x49FDE72: take_gil (ceval_gil.h:250)
==5223==    by 0x4AF7375: PyEval_AcquireThread (ceval.c:456)
==5223==    by 0x4AF72E5: thread_run (_threadmodule.c:1089)
==5223==    by 0x4AC5447: pythread_wrapper (thread_pthread.h:241)
==5223==    by 0x484C9A9: mythread_wrapper (hg_intercepts.c:406)
==5223==    by 0x4E3C906: start_thread (pthread_create.c:444)
==5223==    by 0x4EC2773: clone (clone.S:100)
==5223== 
==5223== ---Thread-Announcement------------------------------------------
==5223== 
==5223== Thread #1 is the program's root thread
==5223== 
==5223== ----------------------------------------------------------------
==5223== 
==5223== Thread #1: pthread_cond_{signal,broadcast}: dubious: associated lock is not held by any thread
==5223==    at 0x4849F1F: pthread_cond_signal_WRK (hg_intercepts.c:1565)
==5223==    by 0x484E1F5: pthread_cond_signal@* (hg_intercepts.c:1586)
==5223==    by 0x4E3BFB5: __pthread_cond_wait_common (pthread_cond_wait.c:516)
==5223==    by 0x4E3BFB5: pthread_cond_timedwait@@GLIBC_2.3.2 (pthread_cond_wait.c:643)
==5223==    by 0x484CE9E: pthread_cond_timedwait_WRK (hg_intercepts.c:1387)
==5223==    by 0x484E1D1: pthread_cond_timedwait@* (hg_intercepts.c:1422)
==5223==    by 0x49FDE72: UnknownInlinedFun (condvar.h:73)
==5223==    by 0x49FDE72: take_gil (ceval_gil.h:250)
==5223==    by 0x4A16345: PyEval_RestoreThread (ceval.c:535)
==5223==    by 0x4AAE6C8: acquire_timed (_threadmodule.c:99)
==5223==    by 0x4AAE0DE: lock_PyThread_acquire_lock (_threadmodule.c:179)
==5223==    by 0x4A32F5D: method_vectorcall_VARARGS_KEYWORDS (descrobject.c:364)
==5223==    by 0x4A25C96: UnknownInlinedFun (pycore_call.h:92)
==5223==    by 0x4A25C96: PyObject_Vectorcall (call.c:299)
==5223==    by 0x4A183D8: _PyEval_EvalFrameDefault (ceval.c:4773)
==5223== 
==5223== ---Thread-Announcement------------------------------------------
==5223== 
==5223== Thread #6 was created
==5223==    at 0x4EC2763: clone (clone.S:76)
==5223==    by 0x4EC2820: __clone_internal (clone-internal.c:83)
==5223==    by 0x4E3C50F: create_thread (pthread_create.c:297)
==5223==    by 0x4E3D073: pthread_create@@GLIBC_2.34 (pthread_create.c:833)
==5223==    by 0x484C7AF: pthread_create_WRK (hg_intercepts.c:445)
==5223==    by 0x484DD35: pthread_create@* (hg_intercepts.c:478)
==5223==    by 0x4AC5317: PyThread_start_new_thread (thread_pthread.h:289)
==5223==    by 0x4AF710D: thread_PyThread_start_new_thread (_threadmodule.c:1162)
==5223==    by 0x4A2C2B7: cfunction_call (methodobject.c:553)
==5223==    by 0x4A0FA92: _PyObject_MakeTpCall (call.c:214)
==5223==    by 0x4A183D8: _PyEval_EvalFrameDefault (ceval.c:4773)
==5223==    by 0x4A144A9: UnknownInlinedFun (pycore_ceval.h:73)
==5223==    by 0x4A144A9: _PyEval_Vector (ceval.c:6438)
==5223== 
==5223== ----------------------------------------------------------------
==5223== 
==5223==  Lock at 0x4D443F8 was first observed
==5223==    at 0x484E0D2: pthread_mutex_init (hg_intercepts.c:818)
==5223==    by 0x4A8EB30: create_gil (ceval_gil.h:107)
==5223==    by 0x4A8EAF9: UnknownInlinedFun (ceval.c:377)
==5223==    by 0x4A8EAF9: init_interp_create_gil (pylifecycle.c:629)
==5223==    by 0x4A8A764: UnknownInlinedFun (pylifecycle.c:666)
==5223==    by 0x4A8A764: UnknownInlinedFun (pylifecycle.c:895)
==5223==    by 0x4A8A764: pyinit_core.constprop.0 (pylifecycle.c:1064)
==5223==    by 0x4A8A3D9: Py_InitializeFromConfig (pylifecycle.c:1254)
==5223==    by 0x4A89FF0: pymain_init (main.c:67)
==5223==    by 0x4A8927F: pymain_main (main.c:701)
==5223==    by 0x4A88F5A: Py_BytesMain (main.c:734)
==5223==    by 0x4DD7B49: (below main) (libc_start_call_main.h:58)
==5223==  Address 0x4d443f8 is in a rw- mapped file /usr/lib64/libpython3.11.so.1.0 segment
==5223== 
==5223== Possible data race during write of size 4 at 0x4D528E0 by thread #6
==5223== Locks held: 1, at address 0x4D443F8
==5223==    at 0x49FDEE6: UnknownInlinedFun (ceval.c:256)
==5223==    by 0x49FDEE6: take_gil (ceval_gil.h:273)
==5223==    by 0x4AF7375: PyEval_AcquireThread (ceval.c:456)
==5223==    by 0x4AF72E5: thread_run (_threadmodule.c:1089)
==5223==    by 0x4AC5447: pythread_wrapper (thread_pthread.h:241)
==5223==    by 0x484C9A9: mythread_wrapper (hg_intercepts.c:406)
==5223==    by 0x4E3C906: start_thread (pthread_create.c:444)
==5223==    by 0x4EC2773: clone (clone.S:100)
==5223== 
==5223== This conflicts with a previous read of size 4 by thread #1
==5223== Locks held: 1, at address 0x4D443F8
==5223==    at 0x49FDD0D: take_gil (ceval_gil.h:312)
==5223==    by 0x4A16345: PyEval_RestoreThread (ceval.c:535)
==5223==    by 0x4AB99A0: internal_close (fileio.c:121)
==5223==    by 0x4AB979F: UnknownInlinedFun (fileio.c:162)
==5223==    by 0x4AB979F: _io_FileIO_close (fileio.c.h:23)
==5223==    by 0x4A375ED: method_vectorcall_NOARGS (descrobject.c:453)
==5223==    by 0x4A13E35: UnknownInlinedFun (pycore_call.h:92)
==5223==    by 0x4A13E35: PyObject_VectorcallMethod (call.c:855)
==5223==    by 0x4AB942F: UnknownInlinedFun (abstract.h:107)
==5223==    by 0x4AB942F: buffered_close (bufferedio.c:506)
==5223==    by 0x4A375ED: method_vectorcall_NOARGS (descrobject.c:453)
==5223==  Address 0x4d528e0 is in a rw- mapped file /usr/lib64/libpython3.11.so.1.0 segment
==5223== 
==5223== ----------------------------------------------------------------
==5223== 
==5223==  Lock at 0x4D443F8 was first observed
==5223==    at 0x484E0D2: pthread_mutex_init (hg_intercepts.c:818)
==5223==    by 0x4A8EB30: create_gil (ceval_gil.h:107)
==5223==    by 0x4A8EAF9: UnknownInlinedFun (ceval.c:377)
==5223==    by 0x4A8EAF9: init_interp_create_gil (pylifecycle.c:629)
==5223==    by 0x4A8A764: UnknownInlinedFun (pylifecycle.c:666)
==5223==    by 0x4A8A764: UnknownInlinedFun (pylifecycle.c:895)
==5223==    by 0x4A8A764: pyinit_core.constprop.0 (pylifecycle.c:1064)
==5223==    by 0x4A8A3D9: Py_InitializeFromConfig (pylifecycle.c:1254)
==5223==    by 0x4A89FF0: pymain_init (main.c:67)
==5223==    by 0x4A8927F: pymain_main (main.c:701)
==5223==    by 0x4A88F5A: Py_BytesMain (main.c:734)
==5223==    by 0x4DD7B49: (below main) (libc_start_call_main.h:58)
==5223==  Address 0x4d443f8 is in a rw- mapped file /usr/lib64/libpython3.11.so.1.0 segment
==5223== 
==5223== Possible data race during write of size 4 at 0x4D528DC by thread #6
==5223== Locks held: 1, at address 0x4D443F8
==5223==    at 0x49FDEED: UnknownInlinedFun (ceval.c:257)
==5223==    by 0x49FDEED: take_gil (ceval_gil.h:273)
==5223==    by 0x4AF7375: PyEval_AcquireThread (ceval.c:456)
==5223==    by 0x4AF72E5: thread_run (_threadmodule.c:1089)
==5223==    by 0x4AC5447: pythread_wrapper (thread_pthread.h:241)
==5223==    by 0x484C9A9: mythread_wrapper (hg_intercepts.c:406)
==5223==    by 0x4E3C906: start_thread (pthread_create.c:444)
==5223==    by 0x4EC2773: clone (clone.S:100)
==5223== 
==5223== This conflicts with a previous read of size 4 by thread #1
==5223== Locks held: none
==5223==    at 0x4A18484: _PyEval_EvalFrameDefault (ceval.c:4792)
==5223==    by 0x4A144A9: UnknownInlinedFun (pycore_ceval.h:73)
==5223==    by 0x4A144A9: _PyEval_Vector (ceval.c:6438)
==5223==    by 0x4A1282E: UnknownInlinedFun (call.c:393)
==5223==    by 0x4A1282E: _PyObject_FastCallDictTstate (call.c:141)
==5223==    by 0x4A3B932: UnknownInlinedFun (call.c:482)
==5223==    by 0x4A3B932: slot_tp_init (typeobject.c:7863)
==5223==    by 0x4A0FC8A: type_call (typeobject.c:1112)
==5223==    by 0x4A0FA92: _PyObject_MakeTpCall (call.c:214)
==5223==    by 0x4A183D8: _PyEval_EvalFrameDefault (ceval.c:4773)
==5223==    by 0x4A144A9: UnknownInlinedFun (pycore_ceval.h:73)
==5223==    by 0x4A144A9: _PyEval_Vector (ceval.c:6438)
==5223==  Address 0x4d528dc is in a rw- mapped file /usr/lib64/libpython3.11.so.1.0 segment
==5223== 
==5223== ----------------------------------------------------------------
==5223== 
==5223==  Lock at 0x4D443F8 was first observed
==5223==    at 0x484E0D2: pthread_mutex_init (hg_intercepts.c:818)
==5223==    by 0x4A8EB30: create_gil (ceval_gil.h:107)
==5223==    by 0x4A8EAF9: UnknownInlinedFun (ceval.c:377)
==5223==    by 0x4A8EAF9: init_interp_create_gil (pylifecycle.c:629)
==5223==    by 0x4A8A764: UnknownInlinedFun (pylifecycle.c:666)
==5223==    by 0x4A8A764: UnknownInlinedFun (pylifecycle.c:895)
==5223==    by 0x4A8A764: pyinit_core.constprop.0 (pylifecycle.c:1064)
==5223==    by 0x4A8A3D9: Py_InitializeFromConfig (pylifecycle.c:1254)
==5223==    by 0x4A89FF0: pymain_init (main.c:67)
==5223==    by 0x4A8927F: pymain_main (main.c:701)
==5223==    by 0x4A88F5A: Py_BytesMain (main.c:734)
==5223==    by 0x4DD7B49: (below main) (libc_start_call_main.h:58)
==5223==  Address 0x4d443f8 is in a rw- mapped file /usr/lib64/libpython3.11.so.1.0 segment
==5223== 
==5223== Possible data race during write of size 4 at 0x4D528E0 by thread #5
==5223== Locks held: 1, at address 0x4D443F8
==5223==    at 0x49FDEE6: UnknownInlinedFun (ceval.c:256)
==5223==    by 0x49FDEE6: take_gil (ceval_gil.h:273)
==5223==    by 0x4A16345: PyEval_RestoreThread (ceval.c:535)
==5223==    by 0x4AB929D: _Py_read (fileutils.c:1775)
==5223==    by 0x4AC4E3E: UnknownInlinedFun (fileio.c:647)
==5223==    by 0x4AC4E3E: _io_FileIO_readinto (fileio.c.h:205)
==5223==    by 0x4A3C2D3: method_vectorcall_O (descrobject.c:481)
==5223==    by 0x4A13E35: UnknownInlinedFun (pycore_call.h:92)
==5223==    by 0x4A13E35: PyObject_VectorcallMethod (call.c:855)
==5223==    by 0x4AC4B9D: UnknownInlinedFun (abstract.h:116)
==5223==    by 0x4AC4B9D: _bufferedreader_raw_read (bufferedio.c:1460)
==5223==    by 0x4AC5391: _bufferedreader_fill_buffer (bufferedio.c:1501)
==5223==    by 0x4AB8F57: UnknownInlinedFun (bufferedio.c:1681)
==5223==    by 0x4AB8F57: UnknownInlinedFun (bufferedio.c:885)
==5223==    by 0x4AB8F57: _io__Buffered_read (bufferedio.c.h:169)
==5223==    by 0x4A19137: _PyEval_EvalFrameDefault (ceval.c:5054)
==5223==    by 0x4A144A9: UnknownInlinedFun (pycore_ceval.h:73)
==5223==    by 0x4A144A9: _PyEval_Vector (ceval.c:6438)
==5223==    by 0x4A4FBAF: UnknownInlinedFun (call.c:393)
==5223==    by 0x4A4FBAF: UnknownInlinedFun (pycore_call.h:92)
==5223==    by 0x4A4FBAF: method_vectorcall (classobject.c:67)
==5223== 
==5223== This conflicts with a previous write of size 4 by thread #6
==5223== Locks held: 1, at address 0x4D443F8
==5223==    at 0x49FDEE6: UnknownInlinedFun (ceval.c:256)
==5223==    by 0x49FDEE6: take_gil (ceval_gil.h:273)
==5223==    by 0x4AF7375: PyEval_AcquireThread (ceval.c:456)
==5223==    by 0x4AF72E5: thread_run (_threadmodule.c:1089)
==5223==    by 0x4AC5447: pythread_wrapper (thread_pthread.h:241)
==5223==    by 0x484C9A9: mythread_wrapper (hg_intercepts.c:406)
==5223==    by 0x4E3C906: start_thread (pthread_create.c:444)
==5223==    by 0x4EC2773: clone (clone.S:100)
==5223==  Address 0x4d528e0 is in a rw- mapped file /usr/lib64/libpython3.11.so.1.0 segment
==5223== 
==5223== ----------------------------------------------------------------
==5223== 
==5223==  Lock at 0x4D443F8 was first observed
==5223==    at 0x484E0D2: pthread_mutex_init (hg_intercepts.c:818)
==5223==    by 0x4A8EB30: create_gil (ceval_gil.h:107)
==5223==    by 0x4A8EAF9: UnknownInlinedFun (ceval.c:377)
==5223==    by 0x4A8EAF9: init_interp_create_gil (pylifecycle.c:629)
==5223==    by 0x4A8A764: UnknownInlinedFun (pylifecycle.c:666)
==5223==    by 0x4A8A764: UnknownInlinedFun (pylifecycle.c:895)
==5223==    by 0x4A8A764: pyinit_core.constprop.0 (pylifecycle.c:1064)
==5223==    by 0x4A8A3D9: Py_InitializeFromConfig (pylifecycle.c:1254)
==5223==    by 0x4A89FF0: pymain_init (main.c:67)
==5223==    by 0x4A8927F: pymain_main (main.c:701)
==5223==    by 0x4A88F5A: Py_BytesMain (main.c:734)
==5223==    by 0x4DD7B49: (below main) (libc_start_call_main.h:58)
==5223==  Address 0x4d443f8 is in a rw- mapped file /usr/lib64/libpython3.11.so.1.0 segment
==5223== 
==5223== Possible data race during write of size 4 at 0x4D528DC by thread #5
==5223== Locks held: 1, at address 0x4D443F8
==5223==    at 0x49FDEED: UnknownInlinedFun (ceval.c:257)
==5223==    by 0x49FDEED: take_gil (ceval_gil.h:273)
==5223==    by 0x4A16345: PyEval_RestoreThread (ceval.c:535)
==5223==    by 0x4AB929D: _Py_read (fileutils.c:1775)
==5223==    by 0x4AC4E3E: UnknownInlinedFun (fileio.c:647)
==5223==    by 0x4AC4E3E: _io_FileIO_readinto (fileio.c.h:205)
==5223==    by 0x4A3C2D3: method_vectorcall_O (descrobject.c:481)
==5223==    by 0x4A13E35: UnknownInlinedFun (pycore_call.h:92)
==5223==    by 0x4A13E35: PyObject_VectorcallMethod (call.c:855)
==5223==    by 0x4AC4B9D: UnknownInlinedFun (abstract.h:116)
==5223==    by 0x4AC4B9D: _bufferedreader_raw_read (bufferedio.c:1460)
==5223==    by 0x4AC5391: _bufferedreader_fill_buffer (bufferedio.c:1501)
==5223==    by 0x4AB8F57: UnknownInlinedFun (bufferedio.c:1681)
==5223==    by 0x4AB8F57: UnknownInlinedFun (bufferedio.c:885)
==5223==    by 0x4AB8F57: _io__Buffered_read (bufferedio.c.h:169)
==5223==    by 0x4A19137: _PyEval_EvalFrameDefault (ceval.c:5054)
==5223==    by 0x4A144A9: UnknownInlinedFun (pycore_ceval.h:73)
==5223==    by 0x4A144A9: _PyEval_Vector (ceval.c:6438)
==5223==    by 0x4A4FBAF: UnknownInlinedFun (call.c:393)
==5223==    by 0x4A4FBAF: UnknownInlinedFun (pycore_call.h:92)
==5223==    by 0x4A4FBAF: method_vectorcall (classobject.c:67)
==5223== 
==5223== This conflicts with a previous write of size 4 by thread #6
==5223== Locks held: 1, at address 0x4D443F8
==5223==    at 0x49FDEED: UnknownInlinedFun (ceval.c:257)
==5223==    by 0x49FDEED: take_gil (ceval_gil.h:273)
==5223==    by 0x4AF7375: PyEval_AcquireThread (ceval.c:456)
==5223==    by 0x4AF72E5: thread_run (_threadmodule.c:1089)
==5223==    by 0x4AC5447: pythread_wrapper (thread_pthread.h:241)
==5223==    by 0x484C9A9: mythread_wrapper (hg_intercepts.c:406)
==5223==    by 0x4E3C906: start_thread (pthread_create.c:444)
==5223==    by 0x4EC2773: clone (clone.S:100)
==5223==  Address 0x4d528dc is in a rw- mapped file /usr/lib64/libpython3.11.so.1.0 segment
==5223== 
==5223== ----------------------------------------------------------------
==5223== 
==5223==  Lock at 0x4D443F8 was first observed
==5223==    at 0x484E0D2: pthread_mutex_init (hg_intercepts.c:818)
==5223==    by 0x4A8EB30: create_gil (ceval_gil.h:107)
==5223==    by 0x4A8EAF9: UnknownInlinedFun (ceval.c:377)
==5223==    by 0x4A8EAF9: init_interp_create_gil (pylifecycle.c:629)
==5223==    by 0x4A8A764: UnknownInlinedFun (pylifecycle.c:666)
==5223==    by 0x4A8A764: UnknownInlinedFun (pylifecycle.c:895)
==5223==    by 0x4A8A764: pyinit_core.constprop.0 (pylifecycle.c:1064)
==5223==    by 0x4A8A3D9: Py_InitializeFromConfig (pylifecycle.c:1254)
==5223==    by 0x4A89FF0: pymain_init (main.c:67)
==5223==    by 0x4A8927F: pymain_main (main.c:701)
==5223==    by 0x4A88F5A: Py_BytesMain (main.c:734)
==5223==    by 0x4DD7B49: (below main) (libc_start_call_main.h:58)
==5223==  Address 0x4d443f8 is in a rw- mapped file /usr/lib64/libpython3.11.so.1.0 segment
==5223== 
==5223== Possible data race during read of size 4 at 0x4D528DC by thread #1
==5223== Locks held: none
==5223==    at 0x4A18484: _PyEval_EvalFrameDefault (ceval.c:4792)
==5223==    by 0x4A144A9: UnknownInlinedFun (pycore_ceval.h:73)
==5223==    by 0x4A144A9: _PyEval_Vector (ceval.c:6438)
==5223==    by 0x4A4FA74: UnknownInlinedFun (call.c:393)
==5223==    by 0x4A4FA74: UnknownInlinedFun (pycore_call.h:92)
==5223==    by 0x4A4FA74: method_vectorcall (classobject.c:89)
==5223==    by 0x4A1C529: _PyEval_EvalFrameDefault (ceval.c:5380)
==5223==    by 0x4A144A9: UnknownInlinedFun (pycore_ceval.h:73)
==5223==    by 0x4A144A9: _PyEval_Vector (ceval.c:6438)
==5223==    by 0x4A128A0: _PyObject_FastCallDictTstate (call.c:152)
==5223==    by 0x4A3BB1B: _PyObject_Call_Prepend (call.c:482)
==5223==    by 0x4ADD521: slot_tp_call (typeobject.c:7632)
==5223==    by 0x4A0FA92: _PyObject_MakeTpCall (call.c:214)
==5223==    by 0x4A183D8: _PyEval_EvalFrameDefault (ceval.c:4773)
==5223==    by 0x4A144A9: UnknownInlinedFun (pycore_ceval.h:73)
==5223==    by 0x4A144A9: _PyEval_Vector (ceval.c:6438)
==5223==    by 0x4A1C529: _PyEval_EvalFrameDefault (ceval.c:5380)
==5223== 
==5223== This conflicts with a previous write of size 4 by thread #3
==5223== Locks held: 1, at address 0x4D443F8
==5223==    at 0x49FDEED: UnknownInlinedFun (ceval.c:257)
==5223==    by 0x49FDEED: take_gil (ceval_gil.h:273)
==5223==    by 0x4A16345: PyEval_RestoreThread (ceval.c:535)
==5223==    by 0x4AB929D: _Py_read (fileutils.c:1775)
==5223==    by 0x4AC4E3E: UnknownInlinedFun (fileio.c:647)
==5223==    by 0x4AC4E3E: _io_FileIO_readinto (fileio.c.h:205)
==5223==    by 0x4A3C2D3: method_vectorcall_O (descrobject.c:481)
==5223==    by 0x4A13E35: UnknownInlinedFun (pycore_call.h:92)
==5223==    by 0x4A13E35: PyObject_VectorcallMethod (call.c:855)
==5223==    by 0x4AC4B9D: UnknownInlinedFun (abstract.h:116)
==5223==    by 0x4AC4B9D: _bufferedreader_raw_read (bufferedio.c:1460)
==5223==    by 0x4AC5391: _bufferedreader_fill_buffer (bufferedio.c:1501)
==5223==  Address 0x4d528dc is in a rw- mapped file /usr/lib64/libpython3.11.so.1.0 segment
==5223== 
==5223== ----------------------------------------------------------------
==5223== 
==5223==  Lock at 0x4D443F8 was first observed
==5223==    at 0x484E0D2: pthread_mutex_init (hg_intercepts.c:818)
==5223==    by 0x4A8EB30: create_gil (ceval_gil.h:107)
==5223==    by 0x4A8EAF9: UnknownInlinedFun (ceval.c:377)
==5223==    by 0x4A8EAF9: init_interp_create_gil (pylifecycle.c:629)
==5223==    by 0x4A8A764: UnknownInlinedFun (pylifecycle.c:666)
==5223==    by 0x4A8A764: UnknownInlinedFun (pylifecycle.c:895)
==5223==    by 0x4A8A764: pyinit_core.constprop.0 (pylifecycle.c:1064)
==5223==    by 0x4A8A3D9: Py_InitializeFromConfig (pylifecycle.c:1254)
==5223==    by 0x4A89FF0: pymain_init (main.c:67)
==5223==    by 0x4A8927F: pymain_main (main.c:701)
==5223==    by 0x4A88F5A: Py_BytesMain (main.c:734)
==5223==    by 0x4DD7B49: (below main) (libc_start_call_main.h:58)
==5223==  Address 0x4d443f8 is in a rw- mapped file /usr/lib64/libpython3.11.so.1.0 segment
==5223== 
==5223== Possible data race during read of size 4 at 0x4D528E0 by thread #1
==5223== Locks held: none
==5223==    at 0x4B160E1: eval_frame_handle_pending (ceval.c:1202)
==5223==    by 0x4A1D130: _PyEval_EvalFrameDefault (ceval.c:1754)
==5223==    by 0x4A144A9: UnknownInlinedFun (pycore_ceval.h:73)
==5223==    by 0x4A144A9: _PyEval_Vector (ceval.c:6438)
==5223==    by 0x4A4FA74: UnknownInlinedFun (call.c:393)
==5223==    by 0x4A4FA74: UnknownInlinedFun (pycore_call.h:92)
==5223==    by 0x4A4FA74: method_vectorcall (classobject.c:89)
==5223==    by 0x4A1C529: _PyEval_EvalFrameDefault (ceval.c:5380)
==5223==    by 0x4A144A9: UnknownInlinedFun (pycore_ceval.h:73)
==5223==    by 0x4A144A9: _PyEval_Vector (ceval.c:6438)
==5223==    by 0x4A128A0: _PyObject_FastCallDictTstate (call.c:152)
==5223==    by 0x4A3BB1B: _PyObject_Call_Prepend (call.c:482)
==5223==    by 0x4ADD521: slot_tp_call (typeobject.c:7632)
==5223==    by 0x4A0FA92: _PyObject_MakeTpCall (call.c:214)
==5223==    by 0x4A183D8: _PyEval_EvalFrameDefault (ceval.c:4773)
==5223==    by 0x4A144A9: UnknownInlinedFun (pycore_ceval.h:73)
==5223==    by 0x4A144A9: _PyEval_Vector (ceval.c:6438)
==5223== 
==5223== This conflicts with a previous write of size 4 by thread #3
==5223== Locks held: 1, at address 0x4D443F8
==5223==    at 0x49FDEE6: UnknownInlinedFun (ceval.c:256)
==5223==    by 0x49FDEE6: take_gil (ceval_gil.h:273)
==5223==    by 0x4A16345: PyEval_RestoreThread (ceval.c:535)
==5223==    by 0x4AB929D: _Py_read (fileutils.c:1775)
==5223==    by 0x4AC4E3E: UnknownInlinedFun (fileio.c:647)
==5223==    by 0x4AC4E3E: _io_FileIO_readinto (fileio.c.h:205)
==5223==    by 0x4A3C2D3: method_vectorcall_O (descrobject.c:481)
==5223==    by 0x4A13E35: UnknownInlinedFun (pycore_call.h:92)
==5223==    by 0x4A13E35: PyObject_VectorcallMethod (call.c:855)
==5223==    by 0x4AC4B9D: UnknownInlinedFun (abstract.h:116)
==5223==    by 0x4AC4B9D: _bufferedreader_raw_read (bufferedio.c:1460)
==5223==    by 0x4AC5391: _bufferedreader_fill_buffer (bufferedio.c:1501)
==5223==  Address 0x4d528e0 is in a rw- mapped file /usr/lib64/libpython3.11.so.1.0 segment
==5223== 
==5223== ---Thread-Announcement------------------------------------------
==5223== 
==5223== Thread #7 was created
==5223==    at 0x4EC2763: clone (clone.S:76)
==5223==    by 0x4EC2820: __clone_internal (clone-internal.c:83)
==5223==    by 0x4E3C50F: create_thread (pthread_create.c:297)
==5223==    by 0x4E3D073: pthread_create@@GLIBC_2.34 (pthread_create.c:833)
==5223==    by 0x484C7AF: pthread_create_WRK (hg_intercepts.c:445)
==5223==    by 0x484DD35: pthread_create@* (hg_intercepts.c:478)
==5223==    by 0x4AC5317: PyThread_start_new_thread (thread_pthread.h:289)
==5223==    by 0x4AF710D: thread_PyThread_start_new_thread (_threadmodule.c:1162)
==5223==    by 0x4A2C2B7: cfunction_call (methodobject.c:553)
==5223==    by 0x4A0FA92: _PyObject_MakeTpCall (call.c:214)
==5223==    by 0x4A183D8: _PyEval_EvalFrameDefault (ceval.c:4773)
==5223==    by 0x4A144A9: UnknownInlinedFun (pycore_ceval.h:73)
==5223==    by 0x4A144A9: _PyEval_Vector (ceval.c:6438)
==5223== 
==5223== ----------------------------------------------------------------
==5223== 
==5223== Thread #7: pthread_cond_{signal,broadcast}: dubious: associated lock is not held by any thread
==5223==    at 0x4849F1F: pthread_cond_signal_WRK (hg_intercepts.c:1565)
==5223==    by 0x484E1F5: pthread_cond_signal@* (hg_intercepts.c:1586)
==5223==    by 0x4E3BFB5: __pthread_cond_wait_common (pthread_cond_wait.c:516)
==5223==    by 0x4E3BFB5: pthread_cond_timedwait@@GLIBC_2.3.2 (pthread_cond_wait.c:643)
==5223==    by 0x484CE9E: pthread_cond_timedwait_WRK (hg_intercepts.c:1387)
==5223==    by 0x484E1D1: pthread_cond_timedwait@* (hg_intercepts.c:1422)
==5223==    by 0x49FDE72: UnknownInlinedFun (condvar.h:73)
==5223==    by 0x49FDE72: take_gil (ceval_gil.h:250)
==5223==    by 0x4AF7375: PyEval_AcquireThread (ceval.c:456)
==5223==    by 0x4AF72E5: thread_run (_threadmodule.c:1089)
==5223==    by 0x4AC5447: pythread_wrapper (thread_pthread.h:241)
==5223==    by 0x484C9A9: mythread_wrapper (hg_intercepts.c:406)
==5223==    by 0x4E3C906: start_thread (pthread_create.c:444)
==5223==    by 0x4EC2773: clone (clone.S:100)
==5223== 
==5223== ----------------------------------------------------------------
==5223== 
==5223== Thread #6: pthread_cond_{signal,broadcast}: dubious: associated lock is not held by any thread
==5223==    at 0x4849F1F: pthread_cond_signal_WRK (hg_intercepts.c:1565)
==5223==    by 0x484E1F5: pthread_cond_signal@* (hg_intercepts.c:1586)
==5223==    by 0x4E3BFB5: __pthread_cond_wait_common (pthread_cond_wait.c:516)
==5223==    by 0x4E3BFB5: pthread_cond_timedwait@@GLIBC_2.3.2 (pthread_cond_wait.c:643)
==5223==    by 0x484CE9E: pthread_cond_timedwait_WRK (hg_intercepts.c:1387)
==5223==    by 0x484E1D1: pthread_cond_timedwait@* (hg_intercepts.c:1422)
==5223==    by 0x49FDE72: UnknownInlinedFun (condvar.h:73)
==5223==    by 0x49FDE72: take_gil (ceval_gil.h:250)
==5223==    by 0x4AF7375: PyEval_AcquireThread (ceval.c:456)
==5223==    by 0x4AF72E5: thread_run (_threadmodule.c:1089)
==5223==    by 0x4AC5447: pythread_wrapper (thread_pthread.h:241)
==5223==    by 0x484C9A9: mythread_wrapper (hg_intercepts.c:406)
==5223==    by 0x4E3C906: start_thread (pthread_create.c:444)
==5223==    by 0x4EC2773: clone (clone.S:100)
==5223== 
==5223== ----------------------------------------------------------------
==5223== 
==5223== Thread #3: pthread_cond_{signal,broadcast}: associated lock is not held by calling thread
==5223==    at 0x4849F1F: pthread_cond_signal_WRK (hg_intercepts.c:1565)
==5223==    by 0x484E1F5: pthread_cond_signal@* (hg_intercepts.c:1586)
==5223==    by 0x4E3BFB5: __pthread_cond_wait_common (pthread_cond_wait.c:516)
==5223==    by 0x4E3BFB5: pthread_cond_timedwait@@GLIBC_2.3.2 (pthread_cond_wait.c:643)
==5223==    by 0x484CE9E: pthread_cond_timedwait_WRK (hg_intercepts.c:1387)
==5223==    by 0x484E1D1: pthread_cond_timedwait@* (hg_intercepts.c:1422)
==5223==    by 0x49FDE72: UnknownInlinedFun (condvar.h:73)
==5223==    by 0x49FDE72: take_gil (ceval_gil.h:250)
==5223==    by 0x4A16345: PyEval_RestoreThread (ceval.c:535)
==5223==    by 0x4AB929D: _Py_read (fileutils.c:1775)
==5223==    by 0x4AC4E3E: UnknownInlinedFun (fileio.c:647)
==5223==    by 0x4AC4E3E: _io_FileIO_readinto (fileio.c.h:205)
==5223==    by 0x4A3C2D3: method_vectorcall_O (descrobject.c:481)
==5223==    by 0x4A13E35: UnknownInlinedFun (pycore_call.h:92)
==5223==    by 0x4A13E35: PyObject_VectorcallMethod (call.c:855)
==5223==    by 0x4AC4B9D: UnknownInlinedFun (abstract.h:116)
==5223==    by 0x4AC4B9D: _bufferedreader_raw_read (bufferedio.c:1460)
==5223== 
==5223== ---Thread-Announcement------------------------------------------
==5223== 
==5223== Thread #8 was created
==5223==    at 0x4EC2763: clone (clone.S:76)
==5223==    by 0x4EC2820: __clone_internal (clone-internal.c:83)
==5223==    by 0x4E3C50F: create_thread (pthread_create.c:297)
==5223==    by 0x4E3D073: pthread_create@@GLIBC_2.34 (pthread_create.c:833)
==5223==    by 0x484C7AF: pthread_create_WRK (hg_intercepts.c:445)
==5223==    by 0x484DD35: pthread_create@* (hg_intercepts.c:478)
==5223==    by 0x4AC5317: PyThread_start_new_thread (thread_pthread.h:289)
==5223==    by 0x4AF710D: thread_PyThread_start_new_thread (_threadmodule.c:1162)
==5223==    by 0x4A2C2B7: cfunction_call (methodobject.c:553)
==5223==    by 0x4A0FA92: _PyObject_MakeTpCall (call.c:214)
==5223==    by 0x4A183D8: _PyEval_EvalFrameDefault (ceval.c:4773)
==5223==    by 0x4A144A9: UnknownInlinedFun (pycore_ceval.h:73)
==5223==    by 0x4A144A9: _PyEval_Vector (ceval.c:6438)
==5223== 
==5223== ----------------------------------------------------------------
==5223== 
==5223== Thread #8: pthread_cond_{signal,broadcast}: dubious: associated lock is not held by any thread
==5223==    at 0x4849F1F: pthread_cond_signal_WRK (hg_intercepts.c:1565)
==5223==    by 0x484E1F5: pthread_cond_signal@* (hg_intercepts.c:1586)
==5223==    by 0x4E3BFB5: __pthread_cond_wait_common (pthread_cond_wait.c:516)
==5223==    by 0x4E3BFB5: pthread_cond_timedwait@@GLIBC_2.3.2 (pthread_cond_wait.c:643)
==5223==    by 0x484CE9E: pthread_cond_timedwait_WRK (hg_intercepts.c:1387)
==5223==    by 0x484E1D1: pthread_cond_timedwait@* (hg_intercepts.c:1422)
==5223==    by 0x49FDE72: UnknownInlinedFun (condvar.h:73)
==5223==    by 0x49FDE72: take_gil (ceval_gil.h:250)
==5223==    by 0x4AF7375: PyEval_AcquireThread (ceval.c:456)
==5223==    by 0x4AF72E5: thread_run (_threadmodule.c:1089)
==5223==    by 0x4AC5447: pythread_wrapper (thread_pthread.h:241)
==5223==    by 0x484C9A9: mythread_wrapper (hg_intercepts.c:406)
==5223==    by 0x4E3C906: start_thread (pthread_create.c:444)
==5223==    by 0x4EC2773: clone (clone.S:100)
==5223== 
==5223== ----------------------------------------------------------------
==5223== 
==5223==  Lock at 0x4D443F8 was first observed
==5223==    at 0x484E0D2: pthread_mutex_init (hg_intercepts.c:818)
==5223==    by 0x4A8EB30: create_gil (ceval_gil.h:107)
==5223==    by 0x4A8EAF9: UnknownInlinedFun (ceval.c:377)
==5223==    by 0x4A8EAF9: init_interp_create_gil (pylifecycle.c:629)
==5223==    by 0x4A8A764: UnknownInlinedFun (pylifecycle.c:666)
==5223==    by 0x4A8A764: UnknownInlinedFun (pylifecycle.c:895)
==5223==    by 0x4A8A764: pyinit_core.constprop.0 (pylifecycle.c:1064)
==5223==    by 0x4A8A3D9: Py_InitializeFromConfig (pylifecycle.c:1254)
==5223==    by 0x4A89FF0: pymain_init (main.c:67)
==5223==    by 0x4A8927F: pymain_main (main.c:701)
==5223==    by 0x4A88F5A: Py_BytesMain (main.c:734)
==5223==    by 0x4DD7B49: (below main) (libc_start_call_main.h:58)
==5223==  Address 0x4d443f8 is in a rw- mapped file /usr/lib64/libpython3.11.so.1.0 segment
==5223== 
==5223== Possible data race during read of size 4 at 0x4D528DC by thread #7
==5223== Locks held: none
==5223==    at 0x4A18484: _PyEval_EvalFrameDefault (ceval.c:4792)
==5223==    by 0x4A144A9: UnknownInlinedFun (pycore_ceval.h:73)
==5223==    by 0x4A144A9: _PyEval_Vector (ceval.c:6438)
==5223==    by 0x4A1C529: _PyEval_EvalFrameDefault (ceval.c:5380)
==5223==    by 0x4A144A9: UnknownInlinedFun (pycore_ceval.h:73)
==5223==    by 0x4A144A9: _PyEval_Vector (ceval.c:6438)
==5223==    by 0x4A4FA74: UnknownInlinedFun (call.c:393)
==5223==    by 0x4A4FA74: UnknownInlinedFun (pycore_call.h:92)
==5223==    by 0x4A4FA74: method_vectorcall (classobject.c:89)
==5223==    by 0x4AF72FF: thread_run (_threadmodule.c:1092)
==5223==    by 0x4AC5447: pythread_wrapper (thread_pthread.h:241)
==5223==    by 0x484C9A9: mythread_wrapper (hg_intercepts.c:406)
==5223==    by 0x4E3C906: start_thread (pthread_create.c:444)
==5223==    by 0x4EC2773: clone (clone.S:100)
==5223== 
==5223== This conflicts with a previous write of size 4 by thread #4
==5223== Locks held: 1, at address 0x4D443F8
==5223==    at 0x49FDEED: UnknownInlinedFun (ceval.c:257)
==5223==    by 0x49FDEED: take_gil (ceval_gil.h:273)
==5223==    by 0x4A16345: PyEval_RestoreThread (ceval.c:535)
==5223==    by 0x4AB929D: _Py_read (fileutils.c:1775)
==5223==    by 0x4AC4E3E: UnknownInlinedFun (fileio.c:647)
==5223==    by 0x4AC4E3E: _io_FileIO_readinto (fileio.c.h:205)
==5223==    by 0x4A3C2D3: method_vectorcall_O (descrobject.c:481)
==5223==    by 0x4A13E35: UnknownInlinedFun (pycore_call.h:92)
==5223==    by 0x4A13E35: PyObject_VectorcallMethod (call.c:855)
==5223==    by 0x4AC4B9D: UnknownInlinedFun (abstract.h:116)
==5223==    by 0x4AC4B9D: _bufferedreader_raw_read (bufferedio.c:1460)
==5223==    by 0x4AC5391: _bufferedreader_fill_buffer (bufferedio.c:1501)
==5223==  Address 0x4d528dc is in a rw- mapped file /usr/lib64/libpython3.11.so.1.0 segment
==5223== 
==5223== ----------------------------------------------------------------
==5223== 
==5223==  Lock at 0x4D443F8 was first observed
==5223==    at 0x484E0D2: pthread_mutex_init (hg_intercepts.c:818)
==5223==    by 0x4A8EB30: create_gil (ceval_gil.h:107)
==5223==    by 0x4A8EAF9: UnknownInlinedFun (ceval.c:377)
==5223==    by 0x4A8EAF9: init_interp_create_gil (pylifecycle.c:629)
==5223==    by 0x4A8A764: UnknownInlinedFun (pylifecycle.c:666)
==5223==    by 0x4A8A764: UnknownInlinedFun (pylifecycle.c:895)
==5223==    by 0x4A8A764: pyinit_core.constprop.0 (pylifecycle.c:1064)
==5223==    by 0x4A8A3D9: Py_InitializeFromConfig (pylifecycle.c:1254)
==5223==    by 0x4A89FF0: pymain_init (main.c:67)
==5223==    by 0x4A8927F: pymain_main (main.c:701)
==5223==    by 0x4A88F5A: Py_BytesMain (main.c:734)
==5223==    by 0x4DD7B49: (below main) (libc_start_call_main.h:58)
==5223==  Address 0x4d443f8 is in a rw- mapped file /usr/lib64/libpython3.11.so.1.0 segment
==5223== 
==5223== Possible data race during read of size 4 at 0x4D528E0 by thread #7
==5223== Locks held: none
==5223==    at 0x4B160E1: eval_frame_handle_pending (ceval.c:1202)
==5223==    by 0x4A1D130: _PyEval_EvalFrameDefault (ceval.c:1754)
==5223==    by 0x4A144A9: UnknownInlinedFun (pycore_ceval.h:73)
==5223==    by 0x4A144A9: _PyEval_Vector (ceval.c:6438)
==5223==    by 0x4A1C529: _PyEval_EvalFrameDefault (ceval.c:5380)
==5223==    by 0x4A144A9: UnknownInlinedFun (pycore_ceval.h:73)
==5223==    by 0x4A144A9: _PyEval_Vector (ceval.c:6438)
==5223==    by 0x4A4FA74: UnknownInlinedFun (call.c:393)
==5223==    by 0x4A4FA74: UnknownInlinedFun (pycore_call.h:92)
==5223==    by 0x4A4FA74: method_vectorcall (classobject.c:89)
==5223==    by 0x4AF72FF: thread_run (_threadmodule.c:1092)
==5223==    by 0x4AC5447: pythread_wrapper (thread_pthread.h:241)
==5223==    by 0x484C9A9: mythread_wrapper (hg_intercepts.c:406)
==5223==    by 0x4E3C906: start_thread (pthread_create.c:444)
==5223==    by 0x4EC2773: clone (clone.S:100)
==5223== 
==5223== This conflicts with a previous write of size 4 by thread #4
==5223== Locks held: 1, at address 0x4D443F8
==5223==    at 0x49FDEE6: UnknownInlinedFun (ceval.c:256)
==5223==    by 0x49FDEE6: take_gil (ceval_gil.h:273)
==5223==    by 0x4A16345: PyEval_RestoreThread (ceval.c:535)
==5223==    by 0x4AB929D: _Py_read (fileutils.c:1775)
==5223==    by 0x4AC4E3E: UnknownInlinedFun (fileio.c:647)
==5223==    by 0x4AC4E3E: _io_FileIO_readinto (fileio.c.h:205)
==5223==    by 0x4A3C2D3: method_vectorcall_O (descrobject.c:481)
==5223==    by 0x4A13E35: UnknownInlinedFun (pycore_call.h:92)
==5223==    by 0x4A13E35: PyObject_VectorcallMethod (call.c:855)
==5223==    by 0x4AC4B9D: UnknownInlinedFun (abstract.h:116)
==5223==    by 0x4AC4B9D: _bufferedreader_raw_read (bufferedio.c:1460)
==5223==    by 0x4AC5391: _bufferedreader_fill_buffer (bufferedio.c:1501)
==5223==  Address 0x4d528e0 is in a rw- mapped file /usr/lib64/libpython3.11.so.1.0 segment
==5223== 
==5223== ----------------------------------------------------------------
==5223== 
==5223==  Lock at 0x4D44450 was first observed
==5223==    at 0x484E0D2: pthread_mutex_init (hg_intercepts.c:818)
==5223==    by 0x4A8EB46: create_gil (ceval_gil.h:109)
==5223==    by 0x4A8EAF9: UnknownInlinedFun (ceval.c:377)
==5223==    by 0x4A8EAF9: init_interp_create_gil (pylifecycle.c:629)
==5223==    by 0x4A8A764: UnknownInlinedFun (pylifecycle.c:666)
==5223==    by 0x4A8A764: UnknownInlinedFun (pylifecycle.c:895)
==5223==    by 0x4A8A764: pyinit_core.constprop.0 (pylifecycle.c:1064)
==5223==    by 0x4A8A3D9: Py_InitializeFromConfig (pylifecycle.c:1254)
==5223==    by 0x4A89FF0: pymain_init (main.c:67)
==5223==    by 0x4A8927F: pymain_main (main.c:701)
==5223==    by 0x4A88F5A: Py_BytesMain (main.c:734)
==5223==    by 0x4DD7B49: (below main) (libc_start_call_main.h:58)
==5223==  Address 0x4d44450 is in a rw- mapped file /usr/lib64/libpython3.11.so.1.0 segment
==5223== 
==5223==  Lock at 0x4D443F8 was first observed
==5223==    at 0x484E0D2: pthread_mutex_init (hg_intercepts.c:818)
==5223==    by 0x4A8EB30: create_gil (ceval_gil.h:107)
==5223==    by 0x4A8EAF9: UnknownInlinedFun (ceval.c:377)
==5223==    by 0x4A8EAF9: init_interp_create_gil (pylifecycle.c:629)
==5223==    by 0x4A8A764: UnknownInlinedFun (pylifecycle.c:666)
==5223==    by 0x4A8A764: UnknownInlinedFun (pylifecycle.c:895)
==5223==    by 0x4A8A764: pyinit_core.constprop.0 (pylifecycle.c:1064)
==5223==    by 0x4A8A3D9: Py_InitializeFromConfig (pylifecycle.c:1254)
==5223==    by 0x4A89FF0: pymain_init (main.c:67)
==5223==    by 0x4A8927F: pymain_main (main.c:701)
==5223==    by 0x4A88F5A: Py_BytesMain (main.c:734)
==5223==    by 0x4DD7B49: (below main) (libc_start_call_main.h:58)
==5223==  Address 0x4d443f8 is in a rw- mapped file /usr/lib64/libpython3.11.so.1.0 segment
==5223== 
==5223== Possible data race during write of size 4 at 0x4D528E0 by thread #7
==5223== Locks held: 1, at address 0x4D44450
==5223==    at 0x4B16018: RESET_GIL_DROP_REQUEST (ceval.c:266)
==5223==    by 0x4A15328: drop_gil (ceval_gil.h:175)
==5223==    by 0x4B16115: eval_frame_handle_pending (ceval.c:1207)
==5223==    by 0x4A1D130: _PyEval_EvalFrameDefault (ceval.c:1754)
==5223==    by 0x4A144A9: UnknownInlinedFun (pycore_ceval.h:73)
==5223==    by 0x4A144A9: _PyEval_Vector (ceval.c:6438)
==5223==    by 0x4A1C529: _PyEval_EvalFrameDefault (ceval.c:5380)
==5223==    by 0x4A144A9: UnknownInlinedFun (pycore_ceval.h:73)
==5223==    by 0x4A144A9: _PyEval_Vector (ceval.c:6438)
==5223==    by 0x4A4FA74: UnknownInlinedFun (call.c:393)
==5223==    by 0x4A4FA74: UnknownInlinedFun (pycore_call.h:92)
==5223==    by 0x4A4FA74: method_vectorcall (classobject.c:89)
==5223==    by 0x4AF72FF: thread_run (_threadmodule.c:1092)
==5223==    by 0x4AC5447: pythread_wrapper (thread_pthread.h:241)
==5223==    by 0x484C9A9: mythread_wrapper (hg_intercepts.c:406)
==5223==    by 0x4E3C906: start_thread (pthread_create.c:444)
==5223== 
==5223== This conflicts with a previous write of size 4 by thread #4
==5223== Locks held: 1, at address 0x4D443F8
==5223==    at 0x49FDEE6: UnknownInlinedFun (ceval.c:256)
==5223==    by 0x49FDEE6: take_gil (ceval_gil.h:273)
==5223==    by 0x4A16345: PyEval_RestoreThread (ceval.c:535)
==5223==    by 0x4AB929D: _Py_read (fileutils.c:1775)
==5223==    by 0x4AC4E3E: UnknownInlinedFun (fileio.c:647)
==5223==    by 0x4AC4E3E: _io_FileIO_readinto (fileio.c.h:205)
==5223==    by 0x4A3C2D3: method_vectorcall_O (descrobject.c:481)
==5223==    by 0x4A13E35: UnknownInlinedFun (pycore_call.h:92)
==5223==    by 0x4A13E35: PyObject_VectorcallMethod (call.c:855)
==5223==    by 0x4AC4B9D: UnknownInlinedFun (abstract.h:116)
==5223==    by 0x4AC4B9D: _bufferedreader_raw_read (bufferedio.c:1460)
==5223==    by 0x4AC5391: _bufferedreader_fill_buffer (bufferedio.c:1501)
==5223==  Address 0x4d528e0 is in a rw- mapped file /usr/lib64/libpython3.11.so.1.0 segment
==5223== 
==5223== ---Thread-Announcement------------------------------------------
==5223== 
==5223== Thread #9 was created
==5223==    at 0x4EC2763: clone (clone.S:76)
==5223==    by 0x4EC2820: __clone_internal (clone-internal.c:83)
==5223==    by 0x4E3C50F: create_thread (pthread_create.c:297)
==5223==    by 0x4E3D073: pthread_create@@GLIBC_2.34 (pthread_create.c:833)
==5223==    by 0x484C7AF: pthread_create_WRK (hg_intercepts.c:445)
==5223==    by 0x484DD35: pthread_create@* (hg_intercepts.c:478)
==5223==    by 0x4AC5317: PyThread_start_new_thread (thread_pthread.h:289)
==5223==    by 0x4AF710D: thread_PyThread_start_new_thread (_threadmodule.c:1162)
==5223==    by 0x4A2C2B7: cfunction_call (methodobject.c:553)
==5223==    by 0x4A0FA92: _PyObject_MakeTpCall (call.c:214)
==5223==    by 0x4A183D8: _PyEval_EvalFrameDefault (ceval.c:4773)
==5223==    by 0x4A144A9: UnknownInlinedFun (pycore_ceval.h:73)
==5223==    by 0x4A144A9: _PyEval_Vector (ceval.c:6438)
==5223== 
==5223== ----------------------------------------------------------------
==5223== 
==5223== Thread #9: pthread_cond_{signal,broadcast}: dubious: associated lock is not held by any thread
==5223==    at 0x4849F1F: pthread_cond_signal_WRK (hg_intercepts.c:1565)
==5223==    by 0x484E1F5: pthread_cond_signal@* (hg_intercepts.c:1586)
==5223==    by 0x4E3BFB5: __pthread_cond_wait_common (pthread_cond_wait.c:516)
==5223==    by 0x4E3BFB5: pthread_cond_timedwait@@GLIBC_2.3.2 (pthread_cond_wait.c:643)
==5223==    by 0x484CE9E: pthread_cond_timedwait_WRK (hg_intercepts.c:1387)
==5223==    by 0x484E1D1: pthread_cond_timedwait@* (hg_intercepts.c:1422)
==5223==    by 0x49FDE72: UnknownInlinedFun (condvar.h:73)
==5223==    by 0x49FDE72: take_gil (ceval_gil.h:250)
==5223==    by 0x4AF7375: PyEval_AcquireThread (ceval.c:456)
==5223==    by 0x4AF72E5: thread_run (_threadmodule.c:1089)
==5223==    by 0x4AC5447: pythread_wrapper (thread_pthread.h:241)
==5223==    by 0x484C9A9: mythread_wrapper (hg_intercepts.c:406)
==5223==    by 0x4E3C906: start_thread (pthread_create.c:444)
==5223==    by 0x4EC2773: clone (clone.S:100)
==5223== 
==5223== ---Thread-Announcement------------------------------------------
==5223== 
==5223== Thread #10 was created
==5223==    at 0x4EC2763: clone (clone.S:76)
==5223==    by 0x4EC2820: __clone_internal (clone-internal.c:83)
==5223==    by 0x4E3C50F: create_thread (pthread_create.c:297)
==5223==    by 0x4E3D073: pthread_create@@GLIBC_2.34 (pthread_create.c:833)
==5223==    by 0x484C7AF: pthread_create_WRK (hg_intercepts.c:445)
==5223==    by 0x484DD35: pthread_create@* (hg_intercepts.c:478)
==5223==    by 0x4AC5317: PyThread_start_new_thread (thread_pthread.h:289)
==5223==    by 0x4AF710D: thread_PyThread_start_new_thread (_threadmodule.c:1162)
==5223==    by 0x4A2C2B7: cfunction_call (methodobject.c:553)
==5223==    by 0x4A0FA92: _PyObject_MakeTpCall (call.c:214)
==5223==    by 0x4A183D8: _PyEval_EvalFrameDefault (ceval.c:4773)
==5223==    by 0x4A144A9: UnknownInlinedFun (pycore_ceval.h:73)
==5223==    by 0x4A144A9: _PyEval_Vector (ceval.c:6438)
==5223== 
==5223== ----------------------------------------------------------------
==5223== 
==5223== Thread #10: pthread_cond_{signal,broadcast}: dubious: associated lock is not held by any thread
==5223==    at 0x4849F1F: pthread_cond_signal_WRK (hg_intercepts.c:1565)
==5223==    by 0x484E1F5: pthread_cond_signal@* (hg_intercepts.c:1586)
==5223==    by 0x4E3BFB5: __pthread_cond_wait_common (pthread_cond_wait.c:516)
==5223==    by 0x4E3BFB5: pthread_cond_timedwait@@GLIBC_2.3.2 (pthread_cond_wait.c:643)
==5223==    by 0x484CE9E: pthread_cond_timedwait_WRK (hg_intercepts.c:1387)
==5223==    by 0x484E1D1: pthread_cond_timedwait@* (hg_intercepts.c:1422)
==5223==    by 0x49FDE72: UnknownInlinedFun (condvar.h:73)
==5223==    by 0x49FDE72: take_gil (ceval_gil.h:250)
==5223==    by 0x4AF7375: PyEval_AcquireThread (ceval.c:456)
==5223==    by 0x4AF72E5: thread_run (_threadmodule.c:1089)
==5223==    by 0x4AC5447: pythread_wrapper (thread_pthread.h:241)
==5223==    by 0x484C9A9: mythread_wrapper (hg_intercepts.c:406)
==5223==    by 0x4E3C906: start_thread (pthread_create.c:444)
==5223==    by 0x4EC2773: clone (clone.S:100)
==5223== 
==5223== ---Thread-Announcement------------------------------------------
==5223== 
==5223== Thread #13 was created
==5223==    at 0x4EC2763: clone (clone.S:76)
==5223==    by 0x4EC2820: __clone_internal (clone-internal.c:83)
==5223==    by 0x4E3C50F: create_thread (pthread_create.c:297)
==5223==    by 0x4E3D073: pthread_create@@GLIBC_2.34 (pthread_create.c:833)
==5223==    by 0x484C7AF: pthread_create_WRK (hg_intercepts.c:445)
==5223==    by 0x484DD35: pthread_create@* (hg_intercepts.c:478)
==5223==    by 0x4AC5317: PyThread_start_new_thread (thread_pthread.h:289)
==5223==    by 0x4AF710D: thread_PyThread_start_new_thread (_threadmodule.c:1162)
==5223==    by 0x4A2C2B7: cfunction_call (methodobject.c:553)
==5223==    by 0x4A0FA92: _PyObject_MakeTpCall (call.c:214)
==5223==    by 0x4A183D8: _PyEval_EvalFrameDefault (ceval.c:4773)
==5223==    by 0x4A144A9: UnknownInlinedFun (pycore_ceval.h:73)
==5223==    by 0x4A144A9: _PyEval_Vector (ceval.c:6438)
==5223== 
==5223== ----------------------------------------------------------------
==5223== 
==5223== Thread #13: pthread_cond_{signal,broadcast}: dubious: associated lock is not held by any thread
==5223==    at 0x4849F1F: pthread_cond_signal_WRK (hg_intercepts.c:1565)
==5223==    by 0x484E1F5: pthread_cond_signal@* (hg_intercepts.c:1586)
==5223==    by 0x4E3BFB5: __pthread_cond_wait_common (pthread_cond_wait.c:516)
==5223==    by 0x4E3BFB5: pthread_cond_timedwait@@GLIBC_2.3.2 (pthread_cond_wait.c:643)
==5223==    by 0x484CE9E: pthread_cond_timedwait_WRK (hg_intercepts.c:1387)
==5223==    by 0x484E1D1: pthread_cond_timedwait@* (hg_intercepts.c:1422)
==5223==    by 0x49FDE72: UnknownInlinedFun (condvar.h:73)
==5223==    by 0x49FDE72: take_gil (ceval_gil.h:250)
==5223==    by 0x4AF7375: PyEval_AcquireThread (ceval.c:456)
==5223==    by 0x4AF72E5: thread_run (_threadmodule.c:1089)
==5223==    by 0x4AC5447: pythread_wrapper (thread_pthread.h:241)
==5223==    by 0x484C9A9: mythread_wrapper (hg_intercepts.c:406)
==5223==    by 0x4E3C906: start_thread (pthread_create.c:444)
==5223==    by 0x4EC2773: clone (clone.S:100)
==5223== 
==5223== ----------------------------------------------------------------
==5223== 
==5223== Possible data race during write of size 4 at 0x4C4F880 by thread #1
==5223== Locks held: none
==5223==    at 0x4A8A184: PyMem_SetAllocator (obmalloc.c:544)
==5223==    by 0x4A893DA: pymem_set_default_allocator (obmalloc.c:251)
==5223==    by 0x4AD7399: _PyRuntimeState_Fini (pystate.c:165)
==5223==    by 0x4AB4FF9: UnknownInlinedFun (pylifecycle.c:131)
==5223==    by 0x4AB4FF9: Py_FinalizeEx (pylifecycle.c:1931)
==5223==    by 0x4AC1DB9: Py_RunMain (main.c:682)
==5223==    by 0x4A88F5A: Py_BytesMain (main.c:734)
==5223==    by 0x4DD7B49: (below main) (libc_start_call_main.h:58)
==5223==  Address 0x4c4f880 is 0 bytes inside data symbol "_PyMem_Raw"
==5223== 
==5223== ----------------------------------------------------------------
==5223== 
==5223== Possible data race during write of size 4 at 0x4C4F880 by thread #1
==5223== Locks held: none
==5223==    at 0x4A8A184: PyMem_SetAllocator (obmalloc.c:544)
==5223==    by 0x4AD73E5: _PyRuntimeState_Fini (pystate.c:177)
==5223==    by 0x4AB4FF9: UnknownInlinedFun (pylifecycle.c:131)
==5223==    by 0x4AB4FF9: Py_FinalizeEx (pylifecycle.c:1931)
==5223==    by 0x4AC1DB9: Py_RunMain (main.c:682)
==5223==    by 0x4A88F5A: Py_BytesMain (main.c:734)
==5223==    by 0x4DD7B49: (below main) (libc_start_call_main.h:58)
==5223==  Address 0x4c4f880 is 0 bytes inside data symbol "_PyMem_Raw"
==5223== 
==5223== 
==5223== Use --history-level=approx or =none to gain increased speed, at
==5223== the cost of reduced accuracy of conflicting-access information
==5223== For lists of detected and suppressed errors, rerun with: -s
==5223== ERROR SUMMARY: 42 errors from 23 contexts (suppressed: 15752 from 71)
